Workbook
Name circuitNumbers: dropdownList!$A$1:$A$21

Sheet masterDataSheet
A1: Master Data Sheet | H1: TRAP | O1: AIR
A2: Lake | B2: Site | C2: Date.time.Deployment | D2: Date.time.LoggerMax | E2: Date.time.Retrieval | F2: Latitude | G2: Longitude | H2: Site Depth.ft | I2: Temperature.C | J2: Volume Collected.mL | K2: Volume Calculated.mL | L2: Normalized Volume.mL | M2: Max Calculated Volume.mL | N2: Sensor Background Voltage | O2: BP.mmHg
A3: Harsha | B3: EUS3 | C3: 2015-05-05 14:00 | D3: NA | E3: 2015-05-07 11:10 | F3: 39.02925 | G3: -84.09093 | H3: NA | I3: NA | J3: =26+26+26+80+140+120 -> 418 | K3: NA | L3: NA | M3: NA | N3: NA | O3: 764.286
A4: Harsha | B4: EUS | C4: =sensorCalcs!C154 -> 2015-09-28 11:46 | D4: 2015-09-29 01:26 | E4: 2015-10-05 14:51 | F4: 39.026410 | G4: -84.091370 | H4: 11 | I4: =sensorCalcs!G154 -> 21.842778 | J4: =29+28+28+(140*6)+90 -> 1015 | K4: =sensorCalcs!O154 -> 386.11896 | L4: =sensorCalcs!U154 -> 5.5870138 | M4: =sensorCalcs!P154 -> 386.28512 | N4: =sensorCalcs!E154 -> 0.17521 | O4: 742.8
A5: Harsha | B5: EUS2 | C5: 2015-05-05 14:00 | D5: NA | E5: 2015-05-07 10:14 | F5: 39.02422 | G5: -84.09095 | H5: NA | I5: NA | J5: =27+29+27.5+(140*7)+70 -> 1133.5 | K5: NA | L5: NA | M5: NA | N5: NA | O5: 764.286
A6: Harsha | B6: EUS2 | C6: 2015-05-07 10:40 | D6: NA | E6: 2015-05-07 12:10 | F6: 39.0243016 | G6: -84.09080 | H6: NA | I6: NA | J6: =140+45 -> 185 | K6: NA | L6: NA | M6: NA | N6: NA | O6: 764.286
A7: Harsha | B7: EEB | C7: 2015-05-05 14:00 | D7: NA | E7: 2015-05-07 11:55 | F7: 39.017303 | G7: -84.103038 | H7: NA | I7: NA | J7: =25+25+28 -> 78 | K7: NA | L7: NA | M7: NA | N7: NA | O7: 764.286
A8: CJ Brown | B8: P3 | C8: 2015-05-06 13:40 | D8: 2015-05-08 18:08 | E8: 2015-05-12 13:48 | F8: NA | G8: NA | H8: NA | I8: NA | J8: =75+27+27+26 -> 155 | K8: =sensorCalcs!O3 -> 123.36368 | L8: NA | M8: =sensorCalcs!P3 -> 123.39872 | N8: =sensorCalcs!E3 -> 0.35165 | O8: 764.794
A9: CJ Brown | B9: P4 | C9: 2015-05-06 13:20 | D9: NA | E9: 2015-05-12 10:24 | F9: NA | G9: NA | H9: NA | I9: NA | J9: 19 | K9: =sensorCalcs!O4 -> 21.312261 | L9: =sensorCalcs!U4 -> 5.5683384 | M9: =sensorCalcs!P4 -> 349.79196 | N9: =sensorCalcs!E4 -> 0.41575 | O9: 764.794
A10: CJ Brown | B10: P2 | C10: 2015-05-06 14:02 | D10: NA | E10: 2015-05-12 12:04 | F10: NA | G10: NA | H10: NA | I10: NA | J10: 5 | K10: =sensorCalcs!O5 -> NA | L10: =sensorCalcs!U5 -> NA | M10: NA | N10: =sensorCalcs!E5 -> 2.49939 | O10: 764.794
A11: CJ Brown | B11: P1 | C11: 2015-05-06 14:36 | D11: NA | E11: 2015-05-12 13:25 | F11: NA | G11: NA | H11: NA | I11: NA | J11: 6.5 | K11: =sensorCalcs!O7 -> NA | L11: =sensorCalcs!U7 -> NA | M11: NA | N11: =sensorCalcs!E7 -> 2.49939 | O11: 764.794
A12: Harsha | B12: EUS2 | C12: 2015-05-07 10:37 | D12: 2015-05-07 19:07 | E12: 2015-05-20 13:00 | F12: NA | G12: NA | H12: NA | I12: NA | J12: 963 | K12: =sensorCalcs!O8 -> 299.55337 | L12: =sensorCalcs!U8 -> 5.5112606 | M12: =sensorCalcs!P8 -> 299.65473 | N12: =sensorCalcs!E8 -> 0.69658 | O12: 764.794
A13: Harsha | B13: EUS | C13: 2015-05-05 14:00 | D13: NA | E13: 2015-05-07 10:30 | F13: 39.02656 | G13: -84.09165 | H13: NA | I13: NA | J13: =25+27+27+140+135 -> 354 | K13: NA | L13: NA | M13: NA | N13: NA | O13: 764.286
A14: Harsha | B14: EUS3 | C14: 2015-05-07 11:27 | D14: 2015-05-09 10:17 | E14: 2015-05-20 14:52 | F14: NA | G14: NA | H14: NA | I14: NA | J14: 796 | K14: =sensorCalcs!O10 -> 379.48755 | L14: =sensorCalcs!U10 -> 5.4795185 | M14: =sensorCalcs!P10 -> 379.58891 | N14: =sensorCalcs!E10 -> 0.21551 | O14: 764.794
A15: Harsha | B15: EEB | C15: 2015-05-07 11:59 | D15: 2015-05-10 04:54 | E15: 2015-05-20 15:32 | F15: NA | G15: NA | H15: NA | I15: NA | J15: 463.5 | K15: =sensorCalcs!O11 -> 138.08404 | L15: =sensorCalcs!U11 -> 1.9437058 | M15: =sensorCalcs!O11 -> 138.08404 | N15: =sensorCalcs!E11 -> 0.21245 | O15: 764.794
A16: Harsha | B16: ECP | C16: 2015-05-07 12:35 | D16: NA | E16: 2015-05-20 15:59 | F16: NA | G16: NA | H16: NA | I16: NA | J16: 12 | K16: =sensorCalcs!O12 -> 4.2649961 | L16: =sensorCalcs!U12 -> 1.9410109 | M16: =sensorCalcs!P12 -> 140.99589 | N16: =sensorCalcs!E12 -> 0.11844 | O16: 764.794
A17: CJ Brown | B17: P4 | C17: 2015-05-12 11:37 | D17: NA | E17: 2015-05-27 15:00 | F17: 39.9687915000 | G17: -87.741670000 | H17: 23 | I17: NA | J17: 249 | K17: =sensorCalcs!O13 -> 242.83841 | L17: =sensorCalcs!U13 -> 5.5420544 | M17: =sensorCalcs!P13 -> 390.29746 | N17: =sensorCalcs!E13 -> 0.16667 | O17: 784.86
A18: CJ Brown | B18: P1 | C18: 2015-05-12 13:30 | D18: NA | E18: 2015-05-27 15:37 | F18: 39.94866 | G18: -83.745296 | H18: NA | I18: NA | J18: 6 | K18: =IF(sensorCalcs!O14<0, 0, sensorCalcs!O14) -> 0 | L18: NA | M18: =sensorCalcs!P14 -> 109.17746 | N18: =sensorCalcs!E14 -> 0.51099 | O18: 784.86
A19: CJ Brown | B19: P2 | C19: 2015-05-12 12:10 | D19: NA | E19: 2015-05-27 16:30 | F19: 39.95901 | G19: -83.739188 | H19: NA | I19: NA | J19: NA | K19: NA | L19: NA | M19: =sensorCalcs!P15 -> 140.51672 | N19: =sensorCalcs!E15 -> 0.17277 | O19: 784.86
A20: Harsha | B20: EUS3 | C20: 2015-05-20 15:11 | D20: 2015-05-21 01:16 | E20: 2015-06-03 11:51 | F20: 39.0292133 | G20: -84.090945 | H20: 12 | I20: NA | J20: 995 | K20: =sensorCalcs!O16 -> 331.27588 | L20: =sensorCalcs!U16 -> 5.5343861 | M20: =sensorCalcs!P16 -> 331.37588 | N20: =sensorCalcs!E16 -> 0.47863 | O20: 763.778
A21: Harsha | B21: EUS | C21: =sensorCalcs!C197 -> 2015-11-04 11:34 | D21: 2015-11-09 23:34 | E21: 2015-11-12 11:04 | F21: 39.026275 | G21: -84.091541 | H21: NA | I21: =sensorCalcs!G197 -> 14.983889 | J21: =(140*6)+5+30+28+29 -> 932 | K21: =sensorCalcs!O197 -> 398.4945 | L21: =sensorCalcs!U197 -> 5.7613117 | M21: =sensorCalcs!P197 -> 398.66066 | N21: =sensorCalcs!E197 -> 0.10073 | O21: 756.666
A22: Harsha | B22: EUS2 | C22: 2015-05-20 13:09 | D22: 2015-05-20 17:19 | E22: 2015-06-03 13:30 | F22: 39.0242000 | G22: -84.09084166 | H22: 10 | I22: NA | J22: 811 | K22: 353.77418 | L22: 351.15634 | M22: 353.77418 | N22: 0.316 | O22: 763.778
A23: Harsha | B23: ECP | C23: 2015-05-20 16:17 | D23: NA | E23: 2015-06-03 13:50 | F23: 39.0121800 | G23: -84.09885166 | H23: 33 | I23: NA | J23: 22.2 | K23: 1.8643116 | L23: 1.8602379 | M23: 100.05139 | N23: 0.888 | O23: 763.778
A24: Harsha | B24: EEB | C24: 2015-05-20 15:46 | D24: 2015-05-24 06:25 | E24: 2015-06-03 14:21 | F24: 39.01726000 | G24: -84.102956666 | H24: 40 | I24: NA | J24: =28+29+28+(140*3)+20 -> 525 | K24: 119.1944 | L24: 119.79508 | M24: 119.1944 | N24: 0.476 | O24: 763.778
A25: Harsha | B25: EOF | C25: 2015-05-29 11:44 | D25: NA | E25: 2015-06-03 15:00 | F25: NA | G25: NA | H25: 102 | I25: NA | J25: 123.5 | K25: =sensorCalcs!O23 -> 99.906057 | L25: =sensorCalcs!U23 -> 1.9498011 | M25: =sensorCalcs!P23 -> 133.48917 | N25: =sensorCalcs!E23 -> 0.26007 | O25: 763.778
A26: Harsha | B26: EFL | C26: 2015-05-29 13:02 | D26: NA | E26: 2015-06-03 15:33 | F26: NA | G26: NA | H26: 44 | I26: NA | J26: 27.13 | K26: =sensorCalcs!O24 -> 16.339623 | L26: =sensorCalcs!U24 -> 1.9453734 | M26: =sensorCalcs!P24 -> 134.72598 | N26: =sensorCalcs!E24 -> 0.36569 | O26: 763.778
A27: Harsha | B27: EMB | C27: =sensorCalcs!C228 -> 2015-11-25 14:57 | D27: NA | E27: 2015-12-02 14:57 | F27: 39.019338 | G27: -84.131072 | H27: NA | I27: =sensorCalcs!G228 -> 12.218889 | J27: =26+13 -> 39 | K27: =sensorCalcs!O228 -> 23.322541 | L27: =sensorCalcs!U228 -> 2.0462248 | M27: =sensorCalcs!P228 -> 128.49705 | N27: =sensorCalcs!E228 -> 0.21612 | O27: 736.2
A28: Harsha | B28: EUS3 | C28: 2015-06-03 11:59 | D28: 2015-06-03 23:54 | E28: 2015-06-10 10:54 | F28: 39.02929 | G28: -84.09094 | H28: 12 | I28: NA | J28: 1725 | K28: =sensorCalcs!O26 -> 343.48585 | L28: =sensorCalcs!U26 -> 5.4534101 | M28: =sensorCalcs!P26 -> 343.58586 | N28: =sensorCalcs!E26 -> 0.40415 | O28: 758.952
A29: Harsha | B29: EUS | C29: =sensorCalcs!C115 -> 2015-08-31 14:10 | D29: 2015-09-01 09:05 | E29: 2015-09-08 13:20 | F29: 39.026491 | G29: -84.0915183 | H29: 11 | I29: NA | J29: =25+25+25+140+140+140+140+140 -> 775 | K29: =sensorCalcs!O115 -> 363.36196 | L29: =sensorCalcs!U115 -> 5.4154829 | M29: =sensorCalcs!P115 -> 363.53312 | N29: =sensorCalcs!E115 -> 0.37607 | O29: 750.2
A30: Harsha | B30: EUS2 | C30: 2015-06-03 13:32 | D30: 2015-06-03 14:32 | E30: 2015-06-10 13:40 | F30: 39.024281 | G30: -84.090958 | H30: 12 | I30: NA | J30: 791 | K30: =sensorCalcs!O28 -> 359.11638 | L30: =sensorCalcs!U28 -> 5.4513294 | M30: =sensorCalcs!P28 -> 359.21876 | N30: =sensorCalcs!E28 -> 0.35958 | O30: 758.952
A31: Harsha | B31: ECP | C31: 2015-06-03 13:58 | D31: NA | E31: 2015-06-10 15:10 | F31: 39.01230 | G31: -84.09877 | H31: 32 | I31: NA | J31: 26.3 | K31: =sensorCalcs!O29 -> 5.5394913 | L31: =sensorCalcs!U29 -> 1.9190558 | M31: =sensorCalcs!P29 -> 108.04991 | N31: =sensorCalcs!E29 -> 0.76129 | O31: 758.952
A32: Harsha | B32: EEB | C32: 2015-06-03 14:23 | D32: 2015-06-05 10:38 | E32: 2015-06-10 14:07 | F32: NA | G32: NA | H32: 40 | I32: NA | J32: 523 | K32: =sensorCalcs!O30 -> 124.28259 | L32: =sensorCalcs!U30 -> 1.9253061 | M32: =sensorCalcs!P30 -> 124.31858 | N32: =sensorCalcs!E30 -> 0.39316 | O32: 758.952
A33: CJ Brown | B33: P4 | C33: 2015-05-27 14:55 | D33: 2015-06-03 05:59 | E33: 2015-06-24 16:34 | F33: 39.968756 | G33: -83.741623 | H33: 24 | I33: NA | J33: 839 | K33: =sensorCalcs!O21 -> 388.15305 | L33: =sensorCalcs!U21 -> 5.4445048 | M33: =sensorCalcs!P21 -> 388.25509 | N33: =sensorCalcs!E21 -> 0.17888 | O33: 742.6
A34: CJ Brown | B34: P1 | C34: 2015-05-27 15:42 | D34: 2015-06-02 08:02 | E34: 2015-06-24 12:16 | F34: 39.948653 | G34: -83.745360 | H34: 38 | I34: NA | J34: 392 | K34: =sensorCalcs!O22 -> 120.77195 | L34: =sensorCalcs!U22 -> 1.9106084 | M34: =sensorCalcs!P22 -> 120.80543 | N34: =sensorCalcs!E22 -> 0.29915 | O34: =AVERAGE(742.6,745.1) -> 743.85
A35: Harsha | B35: EMB | C35: 2015-07-29 12:43 | D35: 2015-07-31 16:13 | E35: 2015-08-05 13:13 | F35: 39.020038 | G35: -84.131073 | H35: 70 | I35: NA | J35: =28+30+29+(140*3)+120 -> 627 | K35: =sensorCalcs!O76 -> 118.59453 | L35: =sensorCalcs!U76 -> 1.9099619 | M35: =sensorCalcs!P76 -> 118.62957 | N35: 0.43468 | O35: 748.2
A36: Harsha | B36: EUS3 | C36: 2015-06-10 11:03 | D36: 2015-06-11 02:13 | E36: 2015-07-01 10:58 | F36: 39.029165 | G36: -84.090903 | H36: 15 | I36: NA | J36: 950 | K36: =sensorCalcs!O34 -> 355.79583 | L36: =sensorCalcs!U34 -> 5.5566455 | M36: =sensorCalcs!P34 -> 355.89583 | N36: =sensorCalcs!E34 -> 0.32906 | O36: 748.9
A37: Harsha | B37: EUS | C37: =sensorCalcs!C143 -> 2015-09-23 13:09 | D37: 2015-09-24 15:39 | E37: 2015-09-28 11:24 | F37: 39.02646 | G37: -84.09150 | H37: 9 | I37: =sensorCalcs!G143 -> 23.641111 | J37: =(140*10)+75+29+28.5+28.5 -> 1561 | K37: =sensorCalcs!O143 -> 386.01761 | L37: =sensorCalcs!U143 -> 5.5425274 | M37: =sensorCalcs!P143 -> 386.18377 | N37: =sensorCalcs!E143 -> 0.17582 | O37: 750.2
A38: Harsha | B38: EUS2 | C38: 2015-06-10 13:46 | D38: 2015-06-11 00:38 | E38: 2015-07-01 13:11 | F38: 39.024216 | G38: -84.090896 | H38: 16 | I38: NA | J38: 593 | K38: =sensorCalcs!O36 -> 379.81272 | L38: =sensorCalcs!U36 -> 5.4750653 | M38: =sensorCalcs!P36 -> 379.9151 | N38: =sensorCalcs!E36 -> 0.23626 | O38: 748.9
A39: Harsha | B39: ECP | C39: 2015-06-10 15:19 | D39: 2015-06-24 13:24 | E39: 2015-07-01 13:54 | F39: NA | G39: NA | H39: 36 | I39: NA | J39: 488 | K39: =sensorCalcs!O37 -> 111.16082 | L39: =sensorCalcs!U37 -> 1.9298462 | M39: =sensorCalcs!P37 -> 111.19873 | N39: =sensorCalcs!E37 -> 0.71062 | O39: 746.7
A40: Harsha | B40: EEB | C40: 2015-06-10 14:18 | D40: 2015-06-11 21:03 | E40: 2015-07-01 14:23 | F40: 39.017275 | G40: -84.102846 | H40: 44 | I40: NA | J40: 605 | K40: 93.172258 | L40: =sensorCalcs!O38 -> 94.058545 | M40: =sensorCalcs!P38 -> 94.094539 | N40: =sensorCalcs!E38 -> 0.90537 | O40: 747.1
...

Sheet sensorCalcs
K1: Height to Volume Conversion | Q1: Temperature Normalization
A2: Lake | B2: Site | C2: Date.time.Deployment | D2: Circuit # from data sheet | E2: background voltage | F2: temperature at sampling.F | G2: temperature at sampling.C | H2: final voltage | I2: BP mm.Hg | J2: Slope from calibration curve (cm/volts) | K2: height.cm | L2: Schedule 40 Pipe.in | M2: Pipe Radius.cm | N2: Cross sectional Area of Pipe.cm2 | O2: Volume calculated.cm3 | P2: Max calculated Volume.cm3 | Q2: Density of Water (kg/m3) | R2: Patm (Pa) | S2: g (m/s2) | T2: Temp. in Degrees Kelvin | U2: Volume normalized to 20 degrees C
A3: CJ Brown | B3: P3 | C3: 2015-05-06 13:40 | D3: 14 | E3: 0.35165 | F3: 68.785 | G3: =CONVERT(F3,"F","C") -> 20.436111 | H3: 2.49939 | I3: NA | J3: =IF(D3=1, 32.2,IF(D3=2, 30.8, IF(D3=3, 29.9, IF(D3=4, 29.6, IF(D3=5, 29.9, IF(D3=6, 30.2, IF(D3=7, 30.4, IF(D3=8, 28, IF(D3=9, 32.2, IF(D3=10, 30.1, IF(D3=11, 30.1, IF(D3=12, 29.2, IF(D3=13, 30.8,IF(D3=14,29.3, IF(D3=15,30.2,IF(D3=16, 30.8,IF(D3=17,30.1,IF(D3=18,29.5,IF(D3=19,28.7,IF(D3=20,30.2,IF(D3=21,31.7, "NOT LISTED"))))))))))))))))))))) -> 29.3 | K3: =J3*(H3-E3) -> 62.928782 | L3: =IF(OR(B3="P4",B3="P5",B3="EUS3",B3="EUS",B3="EUS2"),1,0.5) -> 0.5 | M3: =IF(L3 = 0.5, 0.78994,IF(L3=1, 1.33, "NOT LISTED")) -> 0.78994 | N3: =$M3^2*3.141592 -> 1.9603698 | O3: =K3*N3 -> 123.36368 | P3: =(J3*(2.5-E3))*N3 -> 123.39872 | Q3: =(999.83952+16.945176*G3-0.00798704*G3^2-0.000046170461*G3^3+0.00000010556302*G3^4-0.00000000028054253*G3^5)/(1+0.01689785*G3) -> 997.8402 | R3: =IF(I3="NA", 101325, I3*133.322368) -> 101325 | S3: 9.8 | T3: =G3+273.15 -> 293.58611 | U3: =(1+((Q3*S3/R3/100)*(1+0.01*K3)))*N3*(293/T3) -> 1.9595325
A4: CJ Brown | B4: P4 | C4: 2015-05-06 13:20 | D4: 20 | E4: 0.41575 | F4: 67.199 | G4: =CONVERT(F4,"F","C") -> 19.555 | H4: 0.54274 | I4: NA | J4: =IF(D4=1, 32.2,IF(D4=2, 30.8, IF(D4=3, 29.9, IF(D4=4, 29.6, IF(D4=5, 29.9, IF(D4=6, 30.2, IF(D4=7, 30.4, IF(D4=8, 28, IF(D4=9, 32.2, IF(D4=10, 30.1, IF(D4=11, 30.1, IF(D4=12, 29.2, IF(D4=13, 30.8,IF(D4=14,29.3, IF(D4=15,30.2,IF(D4=16, 30.8,IF(D4=17,30.1,IF(D4=18,29.5,IF(D4=19,28.7,IF(D4=20,30.2,IF(D4=21,31.7, "NOT LISTED"))))))))))))))))))))) -> 30.2 | K4: =J4*(H4-E4) -> 3.835098 | L4: =IF(OR(B4="P4",B4="P5",B4="EUS3",B4="EUS",B4="EUS2"),1,0.5) -> 1 | M4: =IF(L4 = 0.5, 0.78994,IF(L4=1, 1.33, "NOT LISTED")) -> 1.33 | N4: =$M4^2*3.141592 -> 5.5571621 | O4: =K4*N4 -> 21.312261 | P4: =(J4*(2.5-E4))*N4 -> 349.79196 | Q4: =(999.83952+16.945176*G4-0.00798704*G4^2-0.000046170461*G4^3+0.00000010556302*G4^4-0.00000000028054253*G4^5)/(1+0.01689785*G4) -> 998.03082 | R4: =IF(I4="NA", 101325, I4*133.322368) -> 101325 | S4: 9.8 | T4: =G4+273.15 -> 292.705 | U4: =(1+((Q4*S4/R4/100)*(1+0.01*K4)))*N4*(293/T4) -> 5.5683384
A5: CJ Brown | B5: P2 | C5: 2015-05-06 14:02 | D5: 15 | E5: 2.49939 | F5: 69.085 | G5: =CONVERT(F5,"F","C") -> 20.602778 | H5: 2.49939 | I5: NA | J5: =IF(D5=1, 32.2,IF(D5=2, 30.8, IF(D5=3, 29.9, IF(D5=4, 29.6, IF(D5=5, 29.9, IF(D5=6, 30.2, IF(D5=7, 30.4, IF(D5=8, 28, IF(D5=9, 32.2, IF(D5=10, 30.1, IF(D5=11, 30.1, IF(D5=12, 29.2, IF(D5=13, 30.8,IF(D5=14,29.3, IF(D5=15,30.2,IF(D5=16, 30.8,IF(D5=17,30.1,IF(D5=18,29.5,IF(D5=19,28.7,IF(D5=20,30.2,IF(D5=21,31.7, "NOT LISTED"))))))))))))))))))))) -> 30.2 | K5: =J5*(H5-E5) -> 0 | L5: =IF(OR(B5="P4",B5="P5",B5="EUS3",B5="EUS",B5="EUS2"),1,0.5) -> 0.5 | M5: =IF(L5 = 0.5, 0.78994,IF(L5=1, 1.33, "NOT LISTED")) -> 0.78994 | N5: =$M5^2*3.141592 -> 1.9603698 | O5: NA | P5: NA | Q5: =(999.83952+16.945176*G5-0.00798704*G5^2-0.000046170461*G5^3+0.00000010556302*G5^4-0.00000000028054253*G5^5)/(1+0.01689785*G5) -> 997.80326 | R5: =IF(I5="NA", 101325, I5*133.322368) -> 101325 | S5: 9.8 | T5: =G5+273.15 -> 293.75278 | U5: NA
A6: CJ Brown | B6: P5 | C6: 2015-05-06 12:25 | D6: 12 | E6: NA | F6: NA | G6: NA | H6: NA | I6: NA | J6: =IF(D6=1, 32.2,IF(D6=2, 30.8, IF(D6=3, 29.9, IF(D6=4, 29.6, IF(D6=5, 29.9, IF(D6=6, 30.2, IF(D6=7, 30.4, IF(D6=8, 28, IF(D6=9, 32.2, IF(D6=10, 30.1, IF(D6=11, 30.1, IF(D6=12, 29.2, IF(D6=13, 30.8,IF(D6=14,29.3, IF(D6=15,30.2,IF(D6=16, 30.8,IF(D6=17,30.1,IF(D6=18,29.5,IF(D6=19,28.7,IF(D6=20,30.2,IF(D6=21,31.7, "NOT LISTED"))))))))))))))))))))) -> 29.2 | K6: NA | L6: =IF(OR(B6="P4",B6="P5",B6="EUS3",B6="EUS",B6="EUS2"),1,0.5) -> 1 | M6: =IF(L6 = 0.5, 0.78994,IF(L6=1, 1.33, "NOT LISTED")) -> 1.33 | N6: =$M6^2*3.141592 -> 5.5571621 | O6: NA | P6: NA | Q6: =(999.83952+16.945176*G6-0.00798704*G6^2-0.000046170461*G6^3+0.00000010556302*G6^4-0.00000000028054253*G6^5)/(1+0.01689785*G6) -> #VALUE! | R6: =IF(I6="NA", 101325, I6*133.322368) -> 101325 | S6: 9.8 | T6: =G6+273.15 -> #VALUE! | U6: NA
A7: CJ Brown | B7: P1 | C7: 2015-05-06 14:36 | D7: 16 | E7: 2.49939 | F7: 61.075 | G7: =CONVERT(F7,"F","C") -> 16.152778 | H7: 2.49939 | I7: NA | J7: =IF(D7=1, 32.2,IF(D7=2, 30.8, IF(D7=3, 29.9, IF(D7=4, 29.6, IF(D7=5, 29.9, IF(D7=6, 30.2, IF(D7=7, 30.4, IF(D7=8, 28, IF(D7=9, 32.2, IF(D7=10, 30.1, IF(D7=11, 30.1, IF(D7=12, 29.2, IF(D7=13, 30.8,IF(D7=14,29.3, IF(D7=15,30.2,IF(D7=16, 30.8,IF(D7=17,30.1,IF(D7=18,29.5,IF(D7=19,28.7,IF(D7=20,30.2,IF(D7=21,31.7, "NOT LISTED"))))))))))))))))))))) -> 30.8 | K7: =J7*(H7-E7) -> 0 | L7: =IF(OR(B7="P4",B7="P5",B7="EUS3",B7="EUS",B7="EUS2"),1,0.5) -> 0.5 | M7: =IF(L7 = 0.5, 0.78994,IF(L7=1, 1.33, "NOT LISTED")) -> 0.78994 | N7: =$M7^2*3.141592 -> 1.9603698 | O7: NA | P7: NA | Q7: =(999.83952+16.945176*G7-0.00798704*G7^2-0.000046170461*G7^3+0.00000010556302*G7^4-0.00000000028054253*G7^5)/(1+0.01689785*G7) -> 998.68993 | R7: =IF(I7="NA", 101325, I7*133.322368) -> 101325 | S7: 9.8 | T7: =G7+273.15 -> 289.30278 | U7: NA
A8: Harsha | B8: EUS2 | C8: 2015-05-07 10:37 | D8: 3 | E8: 0.69658 | F8: 72.912 | G8: =CONVERT(F8,"F","C") -> 22.728889 | H8: 2.49939 | I8: NA | J8: =IF(D8=1, 32.2,IF(D8=2, 30.8, IF(D8=3, 29.9, IF(D8=4, 29.6, IF(D8=5, 29.9, IF(D8=6, 30.2, IF(D8=7, 30.4, IF(D8=8, 28, IF(D8=9, 32.2, IF(D8=10, 30.1, IF(D8=11, 30.1, IF(D8=12, 29.2, IF(D8=13, 30.8,IF(D8=14,29.3, IF(D8=15,30.2,IF(D8=16, 30.8,IF(D8=17,30.1,IF(D8=18,29.5,IF(D8=19,28.7,IF(D8=20,30.2,IF(D8=21,31.7, "NOT LISTED"))))))))))))))))))))) -> 29.9 | K8: =J8*(H8-E8) -> 53.904019 | L8: =IF(OR(B8="P4",B8="P5",B8="EUS3",B8="EUS",B8="EUS2"),1,0.5) -> 1 | M8: =IF(L8 = 0.5, 0.78994,IF(L8=1, 1.33, "NOT LISTED")) -> 1.33 | N8: =$M8^2*3.141592 -> 5.5571621 | O8: =K8*N8 -> 299.55337 | P8: =(J8*(2.5-E8))*N8 -> 299.65473 | Q8: =(999.83952+16.945176*G8-0.00798704*G8^2-0.000046170461*G8^3+0.00000010556302*G8^4-0.00000000028054253*G8^5)/(1+0.01689785*G8) -> 997.30751 | R8: =IF(I8="NA", 101325, I8*133.322368) -> 101325 | S8: 9.8 | T8: =G8+273.15 -> 295.87889 | U8: =(1+((Q8*S8/R8/100)*(1+0.01*K8)))*N8*(293/T8) -> 5.5112606
A9: Harsha | B9: EUS | C9: 2015-05-07 10:59 | D9: 4 | E9: 0.55189 | F9: 77.335 | G9: =CONVERT(F9,"F","C") -> 25.186111 | H9: 2.49939 | I9: NA | J9: =IF(D9=1, 32.2,IF(D9=2, 30.8, IF(D9=3, 29.9, IF(D9=4, 29.6, IF(D9=5, 29.9, IF(D9=6, 30.2, IF(D9=7, 30.4, IF(D9=8, 28, IF(D9=9, 32.2, IF(D9=10, 30.1, IF(D9=11, 30.1, IF(D9=12, 29.2, IF(D9=13, 30.8,IF(D9=14,29.3, IF(D9=15,30.2,IF(D9=16, 30.8,IF(D9=17,30.1,IF(D9=18,29.5,IF(D9=19,28.7,IF(D9=20,30.2,IF(D9=21,31.7, "NOT LISTED"))))))))))))))))))))) -> 29.6 | K9: =J9*(H9-E9) -> 57.646 | L9: =IF(OR(B9="P4",B9="P5",B9="EUS3",B9="EUS",B9="EUS2"),1,0.5) -> 1 | M9: =IF(L9 = 0.5, 0.78994,IF(L9=1, 1.33, "NOT LISTED")) -> 1.33 | N9: =$M9^2*3.141592 -> 5.5571621 | O9: =K9*N9 -> 320.34817 | P9: =(J9*(2.5-E9))*N9 -> 320.44851 | Q9: =(999.83952+16.945176*G9-0.00798704*G9^2-0.000046170461*G9^3+0.00000010556302*G9^4-0.00000000028054253*G9^5)/(1+0.01689785*G9) -> 996.67995 | R9: =IF(I9="NA", 101325, I9*133.322368) -> 101325 | S9: 9.8 | T9: =G9+273.15 -> 298.33611 | U9: =(1+((Q9*S9/R9/100)*(1+0.01*K9)))*N9*(293/T9) -> 5.4660593
A10: Harsha | B10: EUS3 | C10: 2015-05-07 11:27 | D10: 5 | E10: 0.21551 | F10: 76.071 | G10: =CONVERT(F10,"F","C") -> 24.483889 | H10: 2.49939 | I10: NA | J10: =IF(D10=1, 32.2,IF(D10=2, 30.8, IF(D10=3, 29.9, IF(D10=4, 29.6, IF(D10=5, 29.9, IF(D10=6, 30.2, IF(D10=7, 30.4, IF(D10=8, 28, IF(D10=9, 32.2, IF(D10=10, 30.1, IF(D10=11, 30.1, IF(D10=12, 29.2, IF(D10=13, 30.8,IF(D10=14,29.3, IF(D10=15,30.2,IF(D10=16, 30.8,IF(D10=17,30.1,IF(D10=18,29.5,IF(D10=19,28.7,IF(D10=20,30.2,IF(D10=21,31.7, "NOT LISTED"))))))))))))))))))))) -> 29.9 | K10: =J10*(H10-E10) -> 68.288012 | L10: =IF(OR(B10="P4",B10="P5",B10="EUS3",B10="EUS",B10="EUS2"),1,0.5) -> 1 | M10: =IF(L10 = 0.5, 0.78994,IF(L10=1, 1.33, "NOT LISTED")) -> 1.33 | N10: =$M10^2*3.141592 -> 5.5571621 | O10: =K10*N10 -> 379.48755 | P10: =(J10*(2.5-E10))*N10 -> 379.58891 | Q10: =(999.83952+16.945176*G10-0.00798704*G10^2-0.000046170461*G10^3+0.00000010556302*G10^4-0.00000000028054253*G10^5)/(1+0.01689785*G10) -> 996.86512 | R10: =IF(I10="NA", 101325, I10*133.322368) -> 101325 | S10: 9.8 | T10: =G10+273.15 -> 297.63389 | U10: =(1+((Q10*S10/R10/100)*(1+0.01*K10)))*N10*(293/T10) -> 5.4795185
A11: Harsha | B11: EEB | C11: 2015-05-07 11:59 | D11: 2 | E11: 0.21245 | F11: 73.126 | G11: =CONVERT(F11,"F","C") -> 22.847778 | H11: 2.49939 | I11: NA | J11: =IF(D11=1, 32.2,IF(D11=2, 30.8, IF(D11=3, 29.9, IF(D11=4, 29.6, IF(D11=5, 29.9, IF(D11=6, 30.2, IF(D11=7, 30.4, IF(D11=8, 28, IF(D11=9, 32.2, IF(D11=10, 30.1, IF(D11=11, 30.1, IF(D11=12, 29.2, IF(D11=13, 30.8,IF(D11=14,29.3, IF(D11=15,30.2,IF(D11=16, 30.8,IF(D11=17,30.1,IF(D11=18,29.5,IF(D11=19,28.7,IF(D11=20,30.2,IF(D11=21,31.7, "NOT LISTED"))))))))))))))))))))) -> 30.8 | K11: =J11*(H11-E11) -> 70.437752 | L11: =IF(OR(B11="P4",B11="P5",B11="EUS3",B11="EUS",B11="EUS2"),1,0.5) -> 0.5 | M11: =IF(L11 = 0.5, 0.78994,IF(L11=1, 1.33, "NOT LISTED")) -> 0.78994 | N11: =$M11^2*3.141592 -> 1.9603698 | O11: =K11*N11 -> 138.08404 | P11: =(J11*(2.5-E11))*N11 -> 138.12087 | Q11: =(999.83952+16.945176*G11-0.00798704*G11^2-0.000046170461*G11^3+0.00000010556302*G11^4-0.00000000028054253*G11^5)/(1+0.01689785*G11) -> 997.27848 | R11: =IF(I11="NA", 101325, I11*133.322368) -> 101325 | S11: 9.8 | T11: =G11+273.15 -> 295.99778 | U11: =(1+((Q11*S11/R11/100)*(1+0.01*K11)))*N11*(293/T11) -> 1.9437058
A12: Harsha | B12: ECP | C12: 2015-05-07 12:35 | D12: 6 | E12: 0.11844 | F12: 73.515 | G12: =CONVERT(F12,"F","C") -> 23.063889 | H12: 0.19048 | I12: NA | J12: =IF(D12=1, 32.2,IF(D12=2, 30.8, IF(D12=3, 29.9, IF(D12=4, 29.6, IF(D12=5, 29.9, IF(D12=6, 30.2, IF(D12=7, 30.4, IF(D12=8, 28, IF(D12=9, 32.2, IF(D12=10, 30.1, IF(D12=11, 30.1, IF(D12=12, 29.2, IF(D12=13, 30.8,IF(D12=14,29.3, IF(D12=15,30.2,IF(D12=16, 30.8,IF(D12=17,30.1,IF(D12=18,29.5,IF(D12=19,28.7,IF(D12=20,30.2,IF(D12=21,31.7, "NOT LISTED"))))))))))))))))))))) -> 30.2 | K12: =J12*(H12-E12) -> 2.175608 | L12: =IF(OR(B12="P4",B12="P5",B12="EUS3",B12="EUS",B12="EUS2"),1,0.5) -> 0.5 | M12: =IF(L12 = 0.5, 0.78994,IF(L12=1, 1.33, "NOT LISTED")) -> 0.78994 | N12: =$M12^2*3.141592 -> 1.9603698 | O12: =K12*N12 -> 4.2649961 | P12: =(J12*(2.5-E12))*N12 -> 140.99589 | Q12: =(999.83952+16.945176*G12-0.00798704*G12^2-0.000046170461*G12^3+0.00000010556302*G12^4-0.00000000028054253*G12^5)/(1+0.01689785*G12) -> 997.22535 | R12: =IF(I12="NA", 101325, I12*133.322368) -> 101325 | S12: 9.8 | T12: =G12+273.15 -> 296.21389 | U12: =(1+((Q12*S12/R12/100)*(1+0.01*K12)))*N12*(293/T12) -> 1.9410109
A13: CJ Brown | B13: P4 | C13: 2015-05-12 11:37 | D13: 10 | E13: 0.16667 | F13: 69.901 | G13: =CONVERT(F13,"F","C") -> 21.056111 | H13: 1.61844 | I13: NA | J13: =IF(D13=1, 32.2,IF(D13=2, 30.8, IF(D13=3, 29.9, IF(D13=4, 29.6, IF(D13=5, 29.9, IF(D13=6, 30.2, IF(D13=7, 30.4, IF(D13=8, 28, IF(D13=9, 32.2, IF(D13=10, 30.1, IF(D13=11, 30.1, IF(D13=12, 29.2, IF(D13=13, 30.8,IF(D13=14,29.3, IF(D13=15,30.2,IF(D13=16, 30.8,IF(D13=17,30.1,IF(D13=18,29.5,IF(D13=19,28.7,IF(D13=20,30.2,IF(D13=21,31.7, "NOT LISTED"))))))))))))))))))))) -> 30.1 | K13: =J13*(H13-E13) -> 43.698277 | L13: =IF(OR(B13="P4",B13="P5",B13="EUS3",B13="EUS",B13="EUS2"),1,0.5) -> 1 | M13: =IF(L13 = 0.5, 0.78994,IF(L13=1, 1.33, "NOT LISTED")) -> 1.33 | N13: =$M13^2*3.141592 -> 5.5571621 | O13: =K13*N13 -> 242.83841 | P13: =(J13*(2.5-E13))*N13 -> 390.29746 | Q13: =(999.83952+16.945176*G13-0.00798704*G13^2-0.000046170461*G13^3+0.00000010556302*G13^4-0.00000000028054253*G13^5)/(1+0.01689785*G13) -> 997.70133 | R13: =IF(I13="NA", 101325, I13*133.322368) -> 101325 | S13: 9.8 | T13: =G13+273.15 -> 294.20611 | U13: =(1+((Q13*S13/R13/100)*(1+0.01*K13)))*N13*(293/T13) -> 5.5420544
A14: CJ Brown | B14: P1 | C14: 2015-05-12 13:30 | D14: 8 | E14: 0.51099 | F14: 67.757 | G14: =CONVERT(F14,"F","C") -> 19.865 | H14: 0.41941 | I14: NA | J14: =IF(D14=1, 32.2,IF(D14=2, 30.8, IF(D14=3, 29.9, IF(D14=4, 29.6, IF(D14=5, 29.9, IF(D14=6, 30.2, IF(D14=7, 30.4, IF(D14=8, 28, IF(D14=9, 32.2, IF(D14=10, 30.1, IF(D14=11, 30.1, IF(D14=12, 29.2, IF(D14=13, 30.8,IF(D14=14,29.3, IF(D14=15,30.2,IF(D14=16, 30.8,IF(D14=17,30.1,IF(D14=18,29.5,IF(D14=19,28.7,IF(D14=20,30.2,IF(D14=21,31.7, "NOT LISTED"))))))))))))))))))))) -> 28 | K14: =J14*(H14-E14) -> -2.56424 | L14: =IF(OR(B14="P4",B14="P5",B14="EUS3",B14="EUS",B14="EUS2"),1,0.5) -> 0.5 | M14: =IF(L14 = 0.5, 0.78994,IF(L14=1, 1.33, "NOT LISTED")) -> 0.78994 | N14: =$M14^2*3.141592 -> 1.9603698 | O14: =K14*N14 -> -5.0268585 | P14: =(J14*(2.5-E14))*N14 -> 109.17746 | Q14: =(999.83952+16.945176*G14-0.00798704*G14^2-0.000046170461*G14^3+0.00000010556302*G14^4-0.00000000028054253*G14^5)/(1+0.01689785*G14) -> 997.96467 | R14: =IF(I14="NA", 101325, I14*133.322368) -> 101325 | S14: 9.8 | T14: =G14+273.15 -> 293.015 | U14: =(1+((Q14*S14/R14/100)*(1+0.01*K14)))*N14*(293/T14) -> 1.962113
A15: CJ Brown | B15: P2 | C15: 2015-05-12 12:10 | D15: 13 | E15: 0.17277 | F15: 66.729 | G15: =CONVERT(F15,"F","C") -> 19.293889 | H15: 0.22589 | I15: NA | J15: =IF(D15=1, 32.2,IF(D15=2, 30.8, IF(D15=3, 29.9, IF(D15=4, 29.6, IF(D15=5, 29.9, IF(D15=6, 30.2, IF(D15=7, 30.4, IF(D15=8, 28, IF(D15=9, 32.2, IF(D15=10, 30.1, IF(D15=11, 30.1, IF(D15=12, 29.2, IF(D15=13, 30.8,IF(D15=14,29.3, IF(D15=15,30.2,IF(D15=16, 30.8,IF(D15=17,30.1,IF(D15=18,29.5,IF(D15=19,28.7,IF(D15=20,30.2,IF(D15=21,31.7, "NOT LISTED"))))))))))))))))))))) -> 30.8 | K15: =J15*(H15-E15) -> 1.636096 | L15: =IF(OR(B15="P4",B15="P5",B15="EUS3",B15="EUS",B15="EUS2"),1,0.5) -> 0.5 | M15: =IF(L15 = 0.5, 0.78994,IF(L15=1, 1.33, "NOT LISTED")) -> 0.78994 | N15: =$M15^2*3.141592 -> 1.9603698 | O15: =K15*N15 -> 3.2073531 | P15: =(J15*(2.5-E15))*N15 -> 140.51672 | Q15: =(999.83952+16.945176*G15-0.00798704*G15^2-0.000046170461*G15^3+0.00000010556302*G15^4-0.00000000028054253*G15^5)/(1+0.01689785*G15) -> 998.08577 | R15: =IF(I15="NA", 101325, I15*133.322368) -> 101325 | S15: 9.8 | T15: =G15+273.15 -> 292.44389 | U15: =(1+((Q15*S15/R15/100)*(1+0.01*K15)))*N15*(293/T15) -> 1.9660246
A16: Harsha | B16: EUS3 | C16: 2015-05-20 15:11 | D16: 18 | E16: 0.47863 | F16: 70.716 | G16: =CONVERT(F16,"F","C") -> 21.508889 | H16: 2.49939 | I16: NA | J16: =IF(D16=1, 32.2,IF(D16=2, 30.8, IF(D16=3, 29.9, IF(D16=4, 29.6, IF(D16=5, 29.9, IF(D16=6, 30.2, IF(D16=7, 30.4, IF(D16=8, 28, IF(D16=9, 32.2, IF(D16=10, 30.1, IF(D16=11, 30.1, IF(D16=12, 29.2, IF(D16=13, 30.8,IF(D16=14,29.3, IF(D16=15,30.2,IF(D16=16, 30.8,IF(D16=17,30.1,IF(D16=18,29.5,IF(D16=19,28.7,IF(D16=20,30.2,IF(D16=21,31.7, "NOT LISTED"))))))))))))))))))))) -> 29.5 | K16: =J16*(H16-E16) -> 59.61242 | L16: =IF(OR(B16="P4",B16="P5",B16="EUS3",B16="EUS",B16="EUS2"),1,0.5) -> 1 | M16: =IF(L16 = 0.5, 0.78994,IF(L16=1, 1.33, "NOT LISTED")) -> 1.33 | N16: =$M16^2*3.141592 -> 5.5571621 | O16: =K16*N16 -> 331.27588 | P16: =(J16*(2.5-E16))*N16 -> 331.37588 | Q16: =(999.83952+16.945176*G16-0.00798704*G16^2-0.000046170461*G16^3+0.00000010556302*G16^4-0.00000000028054253*G16^5)/(1+0.01689785*G16) -> 997.59747 | R16: =IF(I16="NA", 101325, I16*133.322368) -> 101325 | S16: 9.8 | T16: =G16+273.15 -> 294.65889 | U16: =(1+((Q16*S16/R16/100)*(1+0.01*K16)))*N16*(293/T16) -> 5.5343861
A17: Harsha | B17: EUS | C17: 2015-05-20 14:37 | D17: 16 | E17: 0.42735 | F17: 72.610 | G17: =CONVERT(F17,"F","C") -> 22.561111 | H17: 2.49939 | I17: NA | J17: =IF(D17=1, 32.2,IF(D17=2, 30.8, IF(D17=3, 29.9, IF(D17=4, 29.6, IF(D17=5, 29.9, IF(D17=6, 30.2, IF(D17=7, 30.4, IF(D17=8, 28, IF(D17=9, 32.2, IF(D17=10, 30.1, IF(D17=11, 30.1, IF(D17=12, 29.2, IF(D17=13, 30.8,IF(D17=14,29.3, IF(D17=15,30.2,IF(D17=16, 30.8,IF(D17=17,30.1,IF(D17=18,29.5,IF(D17=19,28.7,IF(D17=20,30.2,IF(D17=21,31.7, "NOT LISTED"))))))))))))))))))))) -> 30.8 | K17: =J17*(H17-E17) -> 63.818832 | L17: =IF(OR(B17="P4",B17="P5",B17="EUS3",B17="EUS",B17="EUS2"),1,0.5) -> 1 | M17: =IF(L17 = 0.5, 0.78994,IF(L17=1, 1.33, "NOT LISTED")) -> 1.33 | N17: =$M17^2*3.141592 -> 5.5571621 | O17: =K17*N17 -> 354.65159 | P17: =(J17*(2.5-E17))*N17 -> 354.756 | Q17: =(999.83952+16.945176*G17-0.00798704*G17^2-0.000046170461*G17^3+0.00000010556302*G17^4-0.00000000028054253*G17^5)/(1+0.01689785*G17) -> 997.34825 | R17: =IF(I17="NA", 101325, I17*133.322368) -> 101325 | S17: 9.8 | T17: =G17+273.15 -> 295.71111 | U17: =(1+((Q17*S17/R17/100)*(1+0.01*K17)))*N17*(293/T17) -> 5.5149145
A18: Harsha | B18: EUS2 | C18: 2015-05-20 13:09 | D18: 20 | E18: 0.30952 | F18: 71.964 | G18: =CONVERT(F18,"F","C") -> 22.202222 | H18: 2.49939 | I18: NA | J18: =IF(D18=1, 32.2,IF(D18=2, 30.8, IF(D18=3, 29.9, IF(D18=4, 29.6, IF(D18=5, 29.9, IF(D18=6, 30.2, IF(D18=7, 30.4, IF(D18=8, 28, IF(D18=9, 32.2, IF(D18=10, 30.1, IF(D18=11, 30.1, IF(D18=12, 29.2, IF(D18=13, 30.8,IF(D18=14,29.3, IF(D18=15,30.2,IF(D18=16, 30.8,IF(D18=17,30.1,IF(D18=18,29.5,IF(D18=19,28.7,IF(D18=20,30.2,IF(D18=21,31.7, "NOT LISTED"))))))))))))))))))))) -> 30.2 | K18: =J18*(H18-E18) -> 66.134074 | L18: =IF(OR(B18="P4",B18="P5",B18="EUS3",B18="EUS",B18="EUS2"),1,0.5) -> 1 | M18: =IF(L18 = 0.5, 0.78994,IF(L18=1, 1.33, "NOT LISTED")) -> 1.33 | N18: =$M18^2*3.141592 -> 5.5571621 | O18: =K18*N18 -> 367.51777 | P18: =(J18*(2.5-E18))*N18 -> 367.62014 | Q18: =(999.83952+16.945176*G18-0.00798704*G18^2-0.000046170461*G18^3+0.00000010556302*G18^4-0.00000000028054253*G18^5)/(1+0.01689785*G18) -> 997.43448 | R18: =IF(I18="NA", 101325, I18*133.322368) -> 101325 | S18: 9.8 | T18: =G18+273.15 -> 295.35222 | U18: =(1+((Q18*S18/R18/100)*(1+0.01*K18)))*N18*(293/T18) -> 5.5217397
A19: Harsha | B19: ECP | C19: 2015-05-20 16:17 | D19: 21 | E19: 0.88828 | F19: 71.490 | G19: =CONVERT(F19,"F","C") -> 21.938889 | H19: 0.91758 | I19: NA | J19: =IF(D19=1, 32.2,IF(D19=2, 30.8, IF(D19=3, 29.9, IF(D19=4, 29.6, IF(D19=5, 29.9, IF(D19=6, 30.2, IF(D19=7, 30.4, IF(D19=8, 28, IF(D19=9, 32.2, IF(D19=10, 30.1, IF(D19=11, 30.1, IF(D19=12, 29.2, IF(D19=13, 30.8,IF(D19=14,29.3, IF(D19=15,30.2,IF(D19=16, 30.8,IF(D19=17,30.1,IF(D19=18,29.5,IF(D19=19,28.7,IF(D19=20,30.2,IF(D19=21,31.7, "NOT LISTED"))))))))))))))))))))) -> 31.7 | K19: =J19*(H19-E19) -> 0.92881 | L19: =IF(OR(B19="P4",B19="P5",B19="EUS3",B19="EUS",B19="EUS2"),1,0.5) -> 0.5 | M19: =IF(L19 = 0.5, 0.78994,IF(L19=1, 1.33, "NOT LISTED")) -> 0.78994 | N19: =$M19^2*3.141592 -> 1.9603698 | O19: =K19*N19 -> 1.820811 | P19: =(J19*(2.5-E19))*N19 -> 100.15828 | Q19: =(999.83952+16.945176*G19-0.00798704*G19^2-0.000046170461*G19^3+0.00000010556302*G19^4-0.00000000028054253*G19^5)/(1+0.01689785*G19) -> 997.49694 | R19: =IF(I19="NA", 101325, I19*133.322368) -> 101325 | S19: 9.8 | T19: =G19+273.15 -> 295.08889 | U19: =(1+((Q19*S19/R19/100)*(1+0.01*K19)))*N19*(293/T19) -> 1.9483879
... A21: CJ Brown | B21: P4 | C21: 2015-05-27 14:55 | D21: 10 | E21: 0.17888 | F21: 79.524 | G21: =CONVERT(F21,"F","C") -> 26.402222 | H21: 2.49939 | I21: NA | J21: =IF(D21=1, 32.2,IF(D21=2, 30.8, IF(D21=3, 29.9, IF(D21=4, 29.6, IF(D21=5, 29.9, IF(D21=6, 30.2, IF(D21=7, 30.4, IF(D21=8, 28, IF(D21=9, 32.2, IF(D21=10, 30.1, IF(D21=11, 30.1, IF(D21=12, 29.2, IF(D21=13, 30.8,IF(D21=14,29.3, IF(D21=15,30.2,IF(D21=16, 30.8,IF(D21=17,30.1,IF(D21=18,29.5,IF(D21=19,28.7,IF(D21=20,30.2,IF(D21=21,31.7, "NOT LISTED"))))))))))))))))))))) -> 30.1 | K21: =J21*(H21-E21) -> 69.847351 | L21: =IF(OR(B21="P4",B21="P5",B21="EUS3",B21="EUS",B21="EUS2"),1,0.5) -> 1 | M21: =IF(L21 = 0.5, 0.78994,IF(L21=1, 1.33, "NOT LISTED")) -> 1.33 | N21: =$M21^2*3.141592 -> 5.5571621 | O21: =K21*N21 -> 388.15305 | P21: =(J21*(2.5-E21))*N21 -> 388.25509 | Q21: =(999.83952+16.945176*G21-0.00798704*G21^2-0.000046170461*G21^3+0.00000010556302*G21^4-0.00000000028054253*G21^5)/(1+0.01689785*G21) -> 996.34849 | R21: =IF(I21="NA", 101325, I21*133.322368) -> 101325 | S21: 9.8 | T21: =G21+273.15 -> 299.55222 | U21: =(1+((Q21*S21/R21/100)*(1+0.01*K21)))*N21*(293/T21) -> 5.4445048
A22: CJ Brown | B22: P1 | C22: 2015-05-27 15:42 | D22: 8 | E22: 0.29915 | F22: 81.466 | G22: =CONVERT(F22,"F","C") -> 27.481111 | H22: 2.49939 | I22: NA | J22: =IF(D22=1, 32.2,IF(D22=2, 30.8, IF(D22=3, 29.9, IF(D22=4, 29.6, IF(D22=5, 29.9, IF(D22=6, 30.2, IF(D22=7, 30.4, IF(D22=8, 28, IF(D22=9, 32.2, IF(D22=10, 30.1, IF(D22=11, 30.1, IF(D22=12, 29.2, IF(D22=13, 30.8,IF(D22=14,29.3, IF(D22=15,30.2,IF(D22=16, 30.8,IF(D22=17,30.1,IF(D22=18,29.5,IF(D22=19,28.7,IF(D22=20,30.2,IF(D22=21,31.7, "NOT LISTED"))))))))))))))))))))) -> 28 | K22: =J22*(H22-E22) -> 61.60672 | L22: =IF(OR(B22="P4",B22="P5",B22="EUS3",B22="EUS",B22="EUS2"),1,0.5) -> 0.5 | M22: =IF(L22 = 0.5, 0.78994,IF(L22=1, 1.33, "NOT LISTED")) -> 0.78994 | N22: =$M22^2*3.141592 -> 1.9603698 | O22: =K22*N22 -> 120.77195 | P22: =(J22*(2.5-E22))*N22 -> 120.80543 | Q22: =(999.83952+16.945176*G22-0.00798704*G22^2-0.000046170461*G22^3+0.00000010556302*G22^4-0.00000000028054253*G22^5)/(1+0.01689785*G22) -> 996.0432 | R22: =IF(I22="NA", 101325, I22*133.322368) -> 101325 | T22: =G22+273.15 -> 300.63111 | U22: =(1+((Q22*S22/R22/100)*(1+0.01*K22)))*N22*(293/T22) -> 1.9106084
A23: Harsha | B23: EOF | C23: 2015-05-29 11:44 | D23: 7 | E23: 0.26007 | F23: 71.361 | G23: =CONVERT(F23,"F","C") -> 21.867222 | H23: 1.93648 | I23: NA | J23: =IF(D23=1, 32.2,IF(D23=2, 30.8, IF(D23=3, 29.9, IF(D23=4, 29.6, IF(D23=5, 29.9, IF(D23=6, 30.2, IF(D23=7, 30.4, IF(D23=8, 28, IF(D23=9, 32.2, IF(D23=10, 30.1, IF(D23=11, 30.1, IF(D23=12, 29.2, IF(D23=13, 30.8,IF(D23=14,29.3, IF(D23=15,30.2,IF(D23=16, 30.8,IF(D23=17,30.1,IF(D23=18,29.5,IF(D23=19,28.7,IF(D23=20,30.2,IF(D23=21,31.7, "NOT LISTED"))))))))))))))))))))) -> 30.4 | K23: =J23*(H23-E23) -> 50.962864 | L23: =IF(OR(B23="P4",B23="P5",B23="EUS3",B23="EUS",B23="EUS2"),1,0.5) -> 0.5 | M23: =IF(L23 = 0.5, 0.78994,IF(L23=1, 1.33, "NOT LISTED")) -> 0.78994 | N23: =$M23^2*3.141592 -> 1.9603698 | O23: =K23*N23 -> 99.906057 | P23: =(J23*(2.5-E23))*N23 -> 133.48917 | Q23: =(999.83952+16.945176*G23-0.00798704*G23^2-0.000046170461*G23^3+0.00000010556302*G23^4-0.00000000028054253*G23^5)/(1+0.01689785*G23) -> 997.51383 | R23: =IF(I23="NA", 101325, I23*133.322368) -> 101325 | S23: 9.8 | T23: =G23+273.15 -> 295.01722 | U23: =(1+((Q23*S23/R23/100)*(1+0.01*K23)))*N23*(293/T23) -> 1.9498011
A24: Harsha | B24: EFL | C24: 2015-05-29 13:02 | D24: 9 | E24: 0.36569 | F24: 72.351 | G24: =CONVERT(F24,"F","C") -> 22.417222 | H24: 0.62454 | I24: NA | J24: =IF(D24=1, 32.2,IF(D24=2, 30.8, IF(D24=3, 29.9, IF(D24=4, 29.6, IF(D24=5, 29.9, IF(D24=6, 30.2, IF(D24=7, 30.4, IF(D24=8, 28, IF(D24=9, 32.2, IF(D24=10, 30.1, IF(D24=11, 30.1, IF(D24=12, 29.2, IF(D24=13, 30.8,IF(D24=14,29.3, IF(D24=15,30.2,IF(D24=16, 30.8,IF(D24=17,30.1,IF(D24=18,29.5,IF(D24=19,28.7,IF(D24=20,30.2,IF(D24=21,31.7, "NOT LISTED"))))))))))))))))))))) -> 32.2 | K24: =J24*(H24-E24) -> 8.33497 | L24: =IF(OR(B24="P4",B24="P5",B24="EUS3",B24="EUS",B24="EUS2"),1,0.5) -> 0.5 | M24: =IF(L24 = 0.5, 0.78994,IF(L24=1, 1.33, "NOT LISTED")) -> 0.78994 | N24: =$M24^2*3.141592 -> 1.9603698 | O24: =K24*N24 -> 16.339623 | P24: =(J24*(2.5-E24))*N24 -> 134.72598 | Q24: =(999.83952+16.945176*G24-0.00798704*G24^2-0.000046170461*G24^3+0.00000010556302*G24^4-0.00000000028054253*G24^5)/(1+0.01689785*G24) -> 997.38298 | R24: =IF(I24="NA", 101325, I24*133.322368) -> 101325 | S24: 9.8 | T24: =G24+273.15 -> 295.56722 | U24: =(1+((Q24*S24/R24/100)*(1+0.01*K24)))*N24*(293/T24) -> 1.9453734
A25: Harsha | B25: EMB | C25: 2015-05-29 13:36 | D25: 14 | E25: 0.38095 | F25: 71.146 | G25: =CONVERT(F25,"F","C") -> 21.747778 | H25: 1.36691 | I25: NA | J25: =IF(D25=1, 32.2,IF(D25=2, 30.8, IF(D25=3, 29.9, IF(D25=4, 29.6, IF(D25=5, 29.9, IF(D25=6, 30.2, IF(D25=7, 30.4, IF(D25=8, 28, IF(D25=9, 32.2, IF(D25=10, 30.1, IF(D25=11, 30.1, IF(D25=12, 29.2, IF(D25=13, 30.8,IF(D25=14,29.3, IF(D25=15,30.2,IF(D25=16, 30.8,IF(D25=17,30.1,IF(D25=18,29.5,IF(D25=19,28.7,IF(D25=20,30.2,IF(D25=21,31.7, "NOT LISTED"))))))))))))))))))))) -> 29.3 | K25: =J25*(H25-E25) -> 28.888628 | L25: =IF(OR(B25="P4",B25="P5",B25="EUS3",B25="EUS",B25="EUS2"),1,0.5) -> 0.5 | M25: =IF(L25 = 0.5, 0.78994,IF(L25=1, 1.33, "NOT LISTED")) -> 0.78994 | N25: =$M25^2*3.141592 -> 1.9603698 | O25: =K25*N25 -> 56.632393 | P25: =(J25*(2.5-E25))*N25 -> 121.71576 | Q25: =(999.83952+16.945176*G25-0.00798704*G25^2-0.000046170461*G25^3+0.00000010556302*G25^4-0.00000000028054253*G25^5)/(1+0.01689785*G25) -> 997.54185 | R25: =IF(I25="NA", 101325, I25*133.322368) -> 101325 | S25: 9.8 | T25: =G25+273.15 -> 294.89778 | U25: =(1+((Q25*S25/R25/100)*(1+0.01*K25)))*N25*(293/T25) -> 1.9501761
A26: Harsha | B26: EUS3 | C26: 2015-06-03 11:59 | D26: 18 | E26: 0.40415 | F26: 78.602 | G26: =CONVERT(F26,"F","C") -> 25.89 | H26: 2.49939 | I26: NA | J26: =IF(D26=1, 32.2,IF(D26=2, 30.8, IF(D26=3, 29.9, IF(D26=4, 29.6, IF(D26=5, 29.9, IF(D26=6, 30.2, IF(D26=7, 30.4, IF(D26=8, 28, IF(D26=9, 32.2, IF(D26=10, 30.1, IF(D26=11, 30.1, IF(D26=12, 29.2, IF(D26=13, 30.8,IF(D26=14,29.3, IF(D26=15,30.2,IF(D26=16, 30.8,IF(D26=17,30.1,IF(D26=18,29.5,IF(D26=19,28.7,IF(D26=20,30.2,IF(D26=21,31.7, "NOT LISTED"))))))))))))))))))))) -> 29.5 | K26: =J26*(H26-E26) -> 61.80958 | L26: =IF(OR(B26="P4",B26="P5",B26="EUS3",B26="EUS",B26="EUS2"),1,0.5) -> 1 | M26: =IF(L26 = 0.5, 0.78994,IF(L26=1, 1.33, "NOT LISTED")) -> 1.33 | N26: =$M26^2*3.141592 -> 5.5571621 | O26: =K26*N26 -> 343.48585 | P26: =(J26*(2.5-E26))*N26 -> 343.58586 | Q26: =(999.83952+16.945176*G26-0.00798704*G26^2-0.000046170461*G26^3+0.00000010556302*G26^4-0.00000000028054253*G26^5)/(1+0.01689785*G26) -> 996.48975 | R26: =IF(I26="NA", 101325, I26*133.322368) -> 101325 | S26: 9.8 | T26: =G26+273.15 -> 299.04 | U26: =(1+((Q26*S26/R26/100)*(1+0.01*K26)))*N26*(293/T26) -> 5.4534101
A27: Harsha | B27: EUS | C27: 2015-06-03 13:03 | D27: 16 | E27: 0.39255 | F27: 81.997 | G27: =CONVERT(F27,"F","C") -> 27.776111 | H27: 2.49939 | I27: NA | J27: =IF(D27=1, 32.2,IF(D27=2, 30.8, IF(D27=3, 29.9, IF(D27=4, 29.6, IF(D27=5, 29.9, IF(D27=6, 30.2, IF(D27=7, 30.4, IF(D27=8, 28, IF(D27=9, 32.2, IF(D27=10, 30.1, IF(D27=11, 30.1, IF(D27=12, 29.2, IF(D27=13, 30.8,IF(D27=14,29.3, IF(D27=15,30.2,IF(D27=16, 30.8,IF(D27=17,30.1,IF(D27=18,29.5,IF(D27=19,28.7,IF(D27=20,30.2,IF(D27=21,31.7, "NOT LISTED"))))))))))))))))))))) -> 30.8 | K27: =J27*(H27-E27) -> 64.890672 | L27: =IF(OR(B27="P4",B27="P5",B27="EUS3",B27="EUS",B27="EUS2"),1,0.5) -> 1 | M27: =IF(L27 = 0.5, 0.78994,IF(L27=1, 1.33, "NOT LISTED")) -> 1.33 | N27: =$M27^2*3.141592 -> 5.5571621 | O27: =K27*N27 -> 360.60798 | P27: =(J27*(2.5-E27))*N27 -> 360.71239 | Q27: =(999.83952+16.945176*G27-0.00798704*G27^2-0.000046170461*G27^3+0.00000010556302*G27^4-0.00000000028054253*G27^5)/(1+0.01689785*G27) -> 995.95791 | R27: =IF(I27="NA", 101325, I27*133.322368) -> 101325 | S27: 9.8 | T27: =G27+273.15 -> 300.92611 | U27: =(1+((Q27*S27/R27/100)*(1+0.01*K27)))*N27*(293/T27) -> 5.4193859
A28: Harsha | B28: EUS2 | C28: 2015-06-03 13:32 | D28: 20 | E28: 0.35958 | F28: 78.822 | G28: =CONVERT(F28,"F","C") -> 26.012222 | H28: 2.49939 | I28: NA | J28: =IF(D28=1, 32.2,IF(D28=2, 30.8, IF(D28=3, 29.9, IF(D28=4, 29.6, IF(D28=5, 29.9, IF(D28=6, 30.2, IF(D28=7, 30.4, IF(D28=8, 28, IF(D28=9, 32.2, IF(D28=10, 30.1, IF(D28=11, 30.1, IF(D28=12, 29.2, IF(D28=13, 30.8,IF(D28=14,29.3, IF(D28=15,30.2,IF(D28=16, 30.8,IF(D28=17,30.1,IF(D28=18,29.5,IF(D28=19,28.7,IF(D28=20,30.2,IF(D28=21,31.7, "NOT LISTED"))))))))))))))))))))) -> 30.2 | K28: =J28*(H28-E28) -> 64.622262 | L28: =IF(OR(B28="P4",B28="P5",B28="EUS3",B28="EUS",B28="EUS2"),1,0.5) -> 1 | M28: =IF(L28 = 0.5, 0.78994,IF(L28=1, 1.33, "NOT LISTED")) -> 1.33 | N28: =$M28^2*3.141592 -> 5.5571621 | O28: =K28*N28 -> 359.11638 | P28: =(J28*(2.5-E28))*N28 -> 359.21876 | Q28: =(999.83952+16.945176*G28-0.00798704*G28^2-0.000046170461*G28^3+0.00000010556302*G28^4-0.00000000028054253*G28^5)/(1+0.01689785*G28) -> 996.45626 | R28: =IF(I28="NA", 101325, I28*133.322368) -> 101325 | S28: 9.8 | T28: =G28+273.15 -> 299.16222 | U28: =(1+((Q28*S28/R28/100)*(1+0.01*K28)))*N28*(293/T28) -> 5.4513294
A29: Harsha | B29: ECP | C29: 2015-06-03 13:58 | D29: 21 | E29: 0.76129 | F29: 79.084 | G29: =CONVERT(F29,"F","C") -> 26.157778 | H29: 0.85043 | I29: NA | J29: =IF(D29=1, 32.2,IF(D29=2, 30.8, IF(D29=3, 29.9, IF(D29=4, 29.6, IF(D29=5, 29.9, IF(D29=6, 30.2, IF(D29=7, 30.4, IF(D29=8, 28, IF(D29=9, 32.2, IF(D29=10, 30.1, IF(D29=11, 30.1, IF(D29=12, 29.2, IF(D29=13, 30.8,IF(D29=14,29.3, IF(D29=15,30.2,IF(D29=16, 30.8,IF(D29=17,30.1,IF(D29=18,29.5,IF(D29=19,28.7,IF(D29=20,30.2,IF(D29=21,31.7, "NOT LISTED"))))))))))))))))))))) -> 31.7 | K29: =J29*(H29-E29) -> 2.825738 | L29: =IF(OR(B29="P4",B29="P5",B29="EUS3",B29="EUS",B29="EUS2"),1,0.5) -> 0.5 | M29: =IF(L29 = 0.5, 0.78994,IF(L29=1, 1.33, "NOT LISTED")) -> 0.78994 | N29: =$M29^2*3.141592 -> 1.9603698 | O29: =K29*N29 -> 5.5394913 | P29: =(J29*(2.5-E29))*N29 -> 108.04991 | Q29: =(999.83952+16.945176*G29-0.00798704*G29^2-0.000046170461*G29^3+0.00000010556302*G29^4-0.00000000028054253*G29^5)/(1+0.01689785*G29) -> 996.4162 | R29: =IF(I29="NA", 101325, I29*133.322368) -> 101325 | T29: =G29+273.15 -> 299.30778 | U29: =(1+((Q29*S29/R29/100)*(1+0.01*K29)))*N29*(293/T29) -> 1.9190558
A30: Harsha | B30: EEB | C30: 2015-06-03 14:23 | D30: 11 | E30: 0.39316 | F30: 77.335 | G30: =CONVERT(F30,"F","C") -> 25.186111 | H30: 2.49939 | I30: NA | J30: =IF(D30=1, 32.2,IF(D30=2, 30.8, IF(D30=3, 29.9, IF(D30=4, 29.6, IF(D30=5, 29.9, IF(D30=6, 30.2, IF(D30=7, 30.4, IF(D30=8, 28, IF(D30=9, 32.2, IF(D30=10, 30.1, IF(D30=11, 30.1, IF(D30=12, 29.2, IF(D30=13, 30.8,IF(D30=14,29.3, IF(D30=15,30.2,IF(D30=16, 30.8,IF(D30=17,30.1,IF(D30=18,29.5,IF(D30=19,28.7,IF(D30=20,30.2,IF(D30=21,31.7, "NOT LISTED"))))))))))))))))))))) -> 30.1 | K30: =J30*(H30-E30) -> 63.397523 | L30: =IF(OR(B30="P4",B30="P5",B30="EUS3",B30="EUS",B30="EUS2"),1,0.5) -> 0.5 | M30: =IF(L30 = 0.5, 0.78994,IF(L30=1, 1.33, "NOT LISTED")) -> 0.78994 | N30: =$M30^2*3.141592 -> 1.9603698 | O30: =K30*N30 -> 124.28259 | P30: =(J30*(2.5-E30))*N30 -> 124.31858 | Q30: =(999.83952+16.945176*G30-0.00798704*G30^2-0.000046170461*G30^3+0.00000010556302*G30^4-0.00000000028054253*G30^5)/(1+0.01689785*G30) -> 996.67995 | R30: =IF(I30="NA", 101325, I30*133.322368) -> 101325 | T30: =G30+273.15 -> 298.33611 | U30: =(1+((Q30*S30/R30/100)*(1+0.01*K30)))*N30*(293/T30) -> 1.9253061
A31: Harsha | B31: EOF | C31: 2015-06-03 15:06 | D31: 4 | E31: 0.33578 | F31: 79.304 | G31: =CONVERT(F31,"F","C") -> 26.28 | H31: 2.49939 | I31: NA | J31: =IF(D31=1, 32.2,IF(D31=2, 30.8, IF(D31=3, 29.9, IF(D31=4, 29.6, IF(D31=5, 29.9, IF(D31=6, 30.2, IF(D31=7, 30.4, IF(D31=8, 28, IF(D31=9, 32.2, IF(D31=10, 30.1, IF(D31=11, 30.1, IF(D31=12, 29.2, IF(D31=13, 30.8,IF(D31=14,29.3, IF(D31=15,30.2,IF(D31=16, 30.8,IF(D31=17,30.1,IF(D31=18,29.5,IF(D31=19,28.7,IF(D31=20,30.2,IF(D31=21,31.7, "NOT LISTED"))))))))))))))))))))) -> 29.6 | K31: =J31*(H31-E31) -> 64.042856 | L31: =IF(OR(B31="P4",B31="P5",B31="EUS3",B31="EUS",B31="EUS2"),1,0.5) -> 0.5 | M31: =IF(L31 = 0.5, 0.78994,IF(L31=1, 1.33, "NOT LISTED")) -> 0.78994 | N31: =$M31^2*3.141592 -> 1.9603698 | O31: =K31*N31 -> 125.54768 | P31: =(J31*(2.5-E31))*N31 -> 125.58307 | Q31: =(999.83952+16.945176*G31-0.00798704*G31^2-0.000046170461*G31^3+0.00000010556302*G31^4-0.00000000028054253*G31^5)/(1+0.01689785*G31) -> 996.38241 | R31: =IF(I31="NA", 101325, I31*133.322368) -> 101325 | T31: =G31+273.15 -> 299.43 | U31: =(1+((Q31*S31/R31/100)*(1+0.01*K31)))*N31*(293/T31) -> 1.9182725
A32: Harsha | B32: EFL | C32: 2015-06-03 15:39 | D32: 9 | E32: 0.37607 | F32: 78.339 | G32: =CONVERT(F32,"F","C") -> 25.743889 | H32: 2.49939 | I32: NA | J32: =IF(D32=1, 32.2,IF(D32=2, 30.8, IF(D32=3, 29.9, IF(D32=4, 29.6, IF(D32=5, 29.9, IF(D32=6, 30.2, IF(D32=7, 30.4, IF(D32=8, 28, IF(D32=9, 32.2, IF(D32=10, 30.1, IF(D32=11, 30.1, IF(D32=12, 29.2, IF(D32=13, 30.8,IF(D32=14,29.3, IF(D32=15,30.2,IF(D32=16, 30.8,IF(D32=17,30.1,IF(D32=18,29.5,IF(D32=19,28.7,IF(D32=20,30.2,IF(D32=21,31.7, "NOT LISTED"))))))))))))))))))))) -> 32.2 | K32: =J32*(H32-E32) -> 68.370904 | L32: =IF(OR(B32="P4",B32="P5",B32="EUS3",B32="EUS",B32="EUS2"),1,0.5) -> 0.5 | M32: =IF(L32 = 0.5, 0.78994,IF(L32=1, 1.33, "NOT LISTED")) -> 0.78994 | N32: =$M32^2*3.141592 -> 1.9603698 | O32: =K32*N32 -> 134.03225 | P32: =(J32*(2.5-E32))*N32 -> 134.07076 | Q32: =(999.83952+16.945176*G32-0.00798704*G32^2-0.000046170461*G32^3+0.00000010556302*G32^4-0.00000000028054253*G32^5)/(1+0.01689785*G32) -> 996.52961 | R32: =IF(I32="NA", 101325, I32*133.322368) -> 101325 | S32: 9.8 | T32: =G32+273.15 -> 298.89389 | U32: =(1+((Q32*S32/R32/100)*(1+0.01*K32)))*N32*(293/T32) -> 1.9248318
A33: Harsha | B33: EMB | C33: 2015-06-03 15:55 | D33: 14 | E33: 0.5 | F33: 77.29 | G33: =CONVERT(F33,"F","C") -> 25.161111 | H33: 2.49939 | I33: NA | J33: =IF(D33=1, 32.2,IF(D33=2, 30.8, IF(D33=3, 29.9, IF(D33=4, 29.6, IF(D33=5, 29.9, IF(D33=6, 30.2, IF(D33=7, 30.4, IF(D33=8, 28, IF(D33=9, 32.2, IF(D33=10, 30.1, IF(D33=11, 30.1, IF(D33=12, 29.2, IF(D33=13, 30.8,IF(D33=14,29.3, IF(D33=15,30.2,IF(D33=16, 30.8,IF(D33=17,30.1,IF(D33=18,29.5,IF(D33=19,28.7,IF(D33=20,30.2,IF(D33=21,31.7, "NOT LISTED"))))))))))))))))))))) -> 29.3 | K33: =J33*(H33-E33) -> 58.582127 | L33: =IF(OR(B33="P4",B33="P5",B33="EUS3",B33="EUS",B33="EUS2"),1,0.5) -> 0.5 | M33: =IF(L33 = 0.5, 0.78994,IF(L33=1, 1.33, "NOT LISTED")) -> 0.78994 | N33: =$M33^2*3.141592 -> 1.9603698 | O33: =K33*N33 -> 114.84263 | P33: =(J33*(2.5-E33))*N33 -> 114.87767 | Q33: =(999.83952+16.945176*G33-0.00798704*G33^2-0.000046170461*G33^3+0.00000010556302*G33^4-0.00000000028054253*G33^5)/(1+0.01689785*G33) -> 996.68662 | R33: =IF(I33="NA", 101325, I33*133.322368) -> 101325 | T33: =G33+273.15 -> 298.31111 | U33: =(1+((Q33*S33/R33/100)*(1+0.01*K33)))*N33*(293/T33) -> 1.9254675
A34: Harsha | B34: EUS3 | C34: 2015-06-10 11:03 | D34: 18 | E34: 0.32906 | F34: 68.614 | G34: =CONVERT(F34,"F","C") -> 20.341111 | H34: 2.49939 | I34: NA | J34: =IF(D34=1, 32.2,IF(D34=2, 30.8, IF(D34=3, 29.9, IF(D34=4, 29.6, IF(D34=5, 29.9, IF(D34=6, 30.2, IF(D34=7, 30.4, IF(D34=8, 28, IF(D34=9, 32.2, IF(D34=10, 30.1, IF(D34=11, 30.1, IF(D34=12, 29.2, IF(D34=13, 30.8,IF(D34=14,29.3, IF(D34=15,30.2,IF(D34=16, 30.8,IF(D34=17,30.1,IF(D34=18,29.5,IF(D34=19,28.7,IF(D34=20,30.2,IF(D34=21,31.7, "NOT LISTED"))))))))))))))))))))) -> 29.5 | K34: =J34*(H34-E34) -> 64.024735 | L34: =IF(OR(B34="P4",B34="P5",B34="EUS3",B34="EUS",B34="EUS2"),1,0.5) -> 1 | M34: =IF(L34 = 0.5, 0.78994,IF(L34=1, 1.33, "NOT LISTED")) -> 1.33 | N34: =$M34^2*3.141592 -> 5.5571621 | O34: =K34*N34 -> 355.79583 | P34: =(J34*(2.5-E34))*N34 -> 355.89583 | Q34: =(999.83952+16.945176*G34-0.00798704*G34^2-0.000046170461*G34^3+0.00000010556302*G34^4-0.00000000028054253*G34^5)/(1+0.01689785*G34) -> 997.86114 | R34: =IF(I34="NA", 101325, I34*133.322368) -> 101325 | S34: 9.8 | T34: =G34+273.15 -> 293.49111 | U34: =(1+((Q34*S34/R34/100)*(1+0.01*K34)))*N34*(293/T34) -> 5.5566455
A35: Harsha | B35: EUS | C35: 2015-06-10 13:22 | D35: 16 | E35: 0.28510 | F35: 69.085 | G35: =CONVERT(F35,"F","C") -> 20.602778 | H35: 2.49939 | I35: NA | J35: =IF(D35=1, 32.2,IF(D35=2, 30.8, IF(D35=3, 29.9, IF(D35=4, 29.6, IF(D35=5, 29.9, IF(D35=6, 30.2, IF(D35=7, 30.4, IF(D35=8, 28, IF(D35=9, 32.2, IF(D35=10, 30.1, IF(D35=11, 30.1, IF(D35=12, 29.2, IF(D35=13, 30.8,IF(D35=14,29.3, IF(D35=15,30.2,IF(D35=16, 30.8,IF(D35=17,30.1,IF(D35=18,29.5,IF(D35=19,28.7,IF(D35=20,30.2,IF(D35=21,31.7, "NOT LISTED"))))))))))))))))))))) -> 30.8 | K35: =J35*(H35-E35) -> 68.200132 | L35: =IF(OR(B35="P4",B35="P5",B35="EUS3",B35="EUS",B35="EUS2"),1,0.5) -> 1 | M35: =IF(L35 = 0.5, 0.78994,IF(L35=1, 1.33, "NOT LISTED")) -> 1.33 | N35: =$M35^2*3.141592 -> 5.5571621 | O35: =K35*N35 -> 378.99919 | P35: =(J35*(2.5-E35))*N35 -> 379.1036 | Q35: =(999.83952+16.945176*G35-0.00798704*G35^2-0.000046170461*G35^3+0.00000010556302*G35^4-0.00000000028054253*G35^5)/(1+0.01689785*G35) -> 997.80326 | R35: =IF(I35="NA", 101325, I35*133.322368) -> 101325 | S35: 9.8 | T35: =G35+273.15 -> 293.75278 | U35: =(1+((Q35*S35/R35/100)*(1+0.01*K35)))*N35*(293/T35) -> 5.5519186
A36: Harsha | B36: EUS2 | C36: 2015-06-10 13:46 | D36: 20 | E36: 0.23626 | F36: 76.507 | G36: =CONVERT(F36,"F","C") -> 24.726111 | H36: 2.49939 | I36: NA | J36: =IF(D36=1, 32.2,IF(D36=2, 30.8, IF(D36=3, 29.9, IF(D36=4, 29.6, IF(D36=5, 29.9, IF(D36=6, 30.2, IF(D36=7, 30.4, IF(D36=8, 28, IF(D36=9, 32.2, IF(D36=10, 30.1, IF(D36=11, 30.1, IF(D36=12, 29.2, IF(D36=13, 30.8,IF(D36=14,29.3, IF(D36=15,30.2,IF(D36=16, 30.8,IF(D36=17,30.1,IF(D36=18,29.5,IF(D36=19,28.7,IF(D36=20,30.2,IF(D36=21,31.7, "NOT LISTED"))))))))))))))))))))) -> 30.2 | K36: =J36*(H36-E36) -> 68.346526 | L36: =IF(OR(B36="P4",B36="P5",B36="EUS3",B36="EUS",B36="EUS2"),1,0.5) -> 1 | M36: =IF(L36 = 0.5, 0.78994,IF(L36=1, 1.33, "NOT LISTED")) -> 1.33 | N36: =$M36^2*3.141592 -> 5.5571621 | O36: =K36*N36 -> 379.81272 | P36: =(J36*(2.5-E36))*N36 -> 379.9151 | Q36: =(999.83952+16.945176*G36-0.00798704*G36^2-0.000046170461*G36^3+0.00000010556302*G36^4-0.00000000028054253*G36^5)/(1+0.01689785*G36) -> 996.80177 | R36: =IF(I36="NA", 101325, I36*133.322368) -> 101325 | S36: 9.8 | T36: =G36+273.15 -> 297.87611 | U36: =(1+((Q36*S36/R36/100)*(1+0.01*K36)))*N36*(293/T36) -> 5.4750653
A37: Harsha | B37: ECP | C37: 2015-06-10 15:19 | D37: 21 | E37: 0.71062 | F37: 76.881 | G37: =CONVERT(F37,"F","C") -> 24.933889 | H37: 2.49939 | I37: NA | J37: =IF(D37=1, 32.2,IF(D37=2, 30.8, IF(D37=3, 29.9, IF(D37=4, 29.6, IF(D37=5, 29.9, IF(D37=6, 30.2, IF(D37=7, 30.4, IF(D37=8, 28, IF(D37=9, 32.2, IF(D37=10, 30.1, IF(D37=11, 30.1, IF(D37=12, 29.2, IF(D37=13, 30.8,IF(D37=14,29.3, IF(D37=15,30.2,IF(D37=16, 30.8,IF(D37=17,30.1,IF(D37=18,29.5,IF(D37=19,28.7,IF(D37=20,30.2,IF(D37=21,31.7, "NOT LISTED"))))))))))))))))))))) -> 31.7 | K37: =J37*(H37-E37) -> 56.704009 | L37: =IF(OR(B37="P4",B37="P5",B37="EUS3",B37="EUS",B37="EUS2"),1,0.5) -> 0.5 | M37: =IF(L37 = 0.5, 0.78994,IF(L37=1, 1.33, "NOT LISTED")) -> 0.78994 | N37: =$M37^2*3.141592 -> 1.9603698 | O37: =K37*N37 -> 111.16082 | P37: =(J37*(2.5-E37))*N37 -> 111.19873 | Q37: =(999.83952+16.945176*G37-0.00798704*G37^2-0.000046170461*G37^3+0.00000010556302*G37^4-0.00000000028054253*G37^5)/(1+0.01689785*G37) -> 996.74699 | R37: =IF(I37="NA", 101325, I37*133.322368) -> 101325 | S37: 9.8 | T37: =G37+273.15 -> 298.08389 | U37: =(1+((Q37*S37/R37/100)*(1+0.01*K37)))*N37*(293/T37) -> 1.9298462
A38: Harsha | B38: EEB | C38: 2015-06-10 14:18 | D38: 11 | E38: 0.90537 | F38: 76.158 | G38: =CONVERT(F38,"F","C") -> 24.532222 | H38: 2.49939 | I38: NA | J38: =IF(D38=1, 32.2,IF(D38=2, 30.8, IF(D38=3, 29.9, IF(D38=4, 29.6, IF(D38=5, 29.9, IF(D38=6, 30.2, IF(D38=7, 30.4, IF(D38=8, 28, IF(D38=9, 32.2, IF(D38=10, 30.1, IF(D38=11, 30.1, IF(D38=12, 29.2, IF(D38=13, 30.8,IF(D38=14,29.3, IF(D38=15,30.2,IF(D38=16, 30.8,IF(D38=17,30.1,IF(D38=18,29.5,IF(D38=19,28.7,IF(D38=20,30.2,IF(D38=21,31.7, "NOT LISTED"))))))))))))))))))))) -> 30.1 | K38: =J38*(H38-E38) -> 47.980002 | L38: =IF(OR(B38="P4",B38="P5",B38="EUS3",B38="EUS",B38="EUS2"),1,0.5) -> 0.5 | M38: =IF(L38 = 0.5, 0.78994,IF(L38=1, 1.33, "NOT LISTED")) -> 0.78994 | N38: =$M38^2*3.141592 -> 1.9603698 | O38: =K38*N38 -> 94.058545 | P38: =(J38*(2.5-E38))*N38 -> 94.094539 | Q38: =(999.83952+16.945176*G38-0.00798704*G38^2-0.000046170461*G38^3+0.00000010556302*G38^4-0.00000000028054253*G38^5)/(1+0.01689785*G38) -> 996.85252 | R38: =IF(I38="NA", 101325, I38*133.322368) -> 101325 | S38: 9.8 | T38: =G38+273.15 -> 297.68222 | U38: =(1+((Q38*S38/R38/100)*(1+0.01*K38)))*N38*(293/T38) -> 1.9322882
A39: Harsha | B39: ENN | C39: 2015-06-10 10:12 | D39: 3 | E39: 0.69109 | F39: 77.902 | G39: =CONVERT(F39,"F","C") -> 25.501111 | H39: 2.49939 | I39: NA | J39: =IF(D39=1, 32.2,IF(D39=2, 30.8, IF(D39=3, 29.9, IF(D39=4, 29.6, IF(D39=5, 29.9, IF(D39=6, 30.2, IF(D39=7, 30.4, IF(D39=8, 28, IF(D39=9, 32.2, IF(D39=10, 30.1, IF(D39=11, 30.1, IF(D39=12, 29.2, IF(D39=13, 30.8,IF(D39=14,29.3, IF(D39=15,30.2,IF(D39=16, 30.8,IF(D39=17,30.1,IF(D39=18,29.5,IF(D39=19,28.7,IF(D39=20,30.2,IF(D39=21,31.7, "NOT LISTED"))))))))))))))))))))) -> 29.9 | K39: =J39*(H39-E39) -> 54.06817 | L39: =IF(OR(B39="P4",B39="P5",B39="EUS3",B39="EUS",B39="EUS2"),1,0.5) -> 0.5 | M39: =IF(L39 = 0.5, 0.78994,IF(L39=1, 1.33, "NOT LISTED")) -> 0.78994 | N39: =$M39^2*3.141592 -> 1.9603698 | O39: =K39*N39 -> 105.99361 | P39: =(J39*(2.5-E39))*N39 -> 106.02936 | Q39: =(999.83952+16.945176*G39-0.00798704*G39^2-0.000046170461*G39^3+0.00000010556302*G39^4-0.00000000028054253*G39^5)/(1+0.01689785*G39) -> 996.5954 | R39: =IF(I39="NA", 101325, I39*133.322368) -> 101325 | S39: 9.8 | T39: =G39+273.15 -> 298.65111 | U39: =(1+((Q39*S39/R39/100)*(1+0.01*K39)))*N39*(293/T39) -> 1.9261316
A40: CJ Brown | B40: P3 | C40: 2015-06-24 13:25 | D40: 6 | E40: 0.17643 | F40: 74.727 | G40: =CONVERT(F40,"F","C") -> 23.737222 | H40: 2.49939 | I40: NA | J40: =IF(D40=1, 32.2,IF(D40=2, 30.8, IF(D40=3, 29.9, IF(D40=4, 29.6, IF(D40=5, 29.9, IF(D40=6, 30.2, IF(D40=7, 30.4, IF(D40=8, 28, IF(D40=9, 32.2, IF(D40=10, 30.1, IF(D40=11, 30.1, IF(D40=12, 29.2, IF(D40=13, 30.8,IF(D40=14,29.3, IF(D40=15,30.2,IF(D40=16, 30.8,IF(D40=17,30.1,IF(D40=18,29.5,IF(D40=19,28.7,IF(D40=20,30.2,IF(D40=21,31.7, "NOT LISTED"))))))))))))))))))))) -> 30.2 | K40: =J40*(H40-E40) -> 70.153392 | L40: =IF(OR(B40="P4",B40="P5",B40="EUS3",B40="EUS",B40="EUS2"),1,0.5) -> 0.5 | M40: =IF(L40 = 0.5, 0.78994,IF(L40=1, 1.33, "NOT LISTED")) -> 0.78994 | N40: =$M40^2*3.141592 -> 1.9603698 | O40: =K40*N40 -> 137.52659 | P40: =(J40*(2.5-E40))*N40 -> 137.5627 | Q40: =(999.83952+16.945176*G40-0.00798704*G40^2-0.000046170461*G40^3+0.00000010556302*G40^4-0.00000000028054253*G40^5)/(1+0.01689785*G40) -> 997.05693 | R40: =IF(I40="NA", 101325, I40*133.322368) -> 101325 | S40: 9.8 | T40: =G40+273.15 -> 296.88722 | U40: =(1+((Q40*S40/R40/100)*(1+0.01*K40)))*N40*(293/T40) -> 1.9378767
A41: CJ Brown | B41: P1 | C41: 2015-06-24 14:21 | D41: 8 | E41: 0.43040 | F41: 74.511 | G41: =CONVERT(F41,"F","C") -> 23.617222 | H41: 2.49939 | I41: NA | J41: =IF(D41=1, 32.2,IF(D41=2, 30.8, IF(D41=3, 29.9, IF(D41=4, 29.6, IF(D41=5, 29.9, IF(D41=6, 30.2, IF(D41=7, 30.4, IF(D41=8, 28, IF(D41=9, 32.2, IF(D41=10, 30.1, IF(D41=11, 30.1, IF(D41=12, 29.2, IF(D41=13, 30.8,IF(D41=14,29.3, IF(D41=15,30.2,IF(D41=16, 30.8,IF(D41=17,30.1,IF(D41=18,29.5,IF(D41=19,28.7,IF(D41=20,30.2,IF(D41=21,31.7, "NOT LISTED"))))))))))))))))))))) -> 28 | K41: =J41*(H41-E41) -> 57.93172 | L41: =IF(OR(B41="P4",B41="P5",B41="EUS3",B41="EUS",B41="EUS2"),1,0.5) -> 0.5 | M41: =IF(L41 = 0.5, 0.78994,IF(L41=1, 1.33, "NOT LISTED")) -> 0.78994 | N41: =$M41^2*3.141592 -> 1.9603698 | O41: =K41*N41 -> 113.56759 | P41: =(J41*(2.5-E41))*N41 -> 113.60107 | Q41: =(999.83952+16.945176*G41-0.00798704*G41^2-0.000046170461*G41^3+0.00000010556302*G41^4-0.00000000028054253*G41^5)/(1+0.01689785*G41) -> 997.08726 | R41: =IF(I41="NA", 101325, I41*133.322368) -> 101325 | S41: 9.8 | T41: =G41+273.15 -> 296.76722 | U41: =(1+((Q41*S41/R41/100)*(1+0.01*K41)))*N41*(293/T41) -> 1.9384323
...

Sheet sondeData
A1: Lake | B1: Site | C1: Sample.Date | D1: Sample.depth.ft | E1: Temp.C | F1: DO.percent | G1: DO.mg/L | H1: sp.Cond.us/cm | I1: pH | J1: ORP | K1: Turbidity.nt
A2: Harsha | B2: EEB | C2: 2015-06-10 | D2: 0.95 | E2: 25.72 | F2: 216.1 | G2: 17.61 | H2: 259 | I2: 6.66 | J2: NA | K2: 21.1
A3: Harsha | B3: EEB | C3: 2015-06-10 | D3: 37.11 | E3: 13.28 | F3: 3.8 | G3: 0.39 | H3: 275 | I3: 6.59 | J3: NA | K3: 47
A4: Harsha | B4: EUS3 | C4: 2015-06-10 | D4: 1.64 | E4: 25.7 | F4: 205.4 | G4: 16.09 | H4: 306 | I4: 11.36 | J4: NA | K4: 43
A5: Harsha | B5: EUS3 | C5: 2015-06-10 | D5: 7.2 | E5: 23.76 | F5: 57.1 | G5: 4.8 | H5: 318 | I5: 10.86 | J5: NA | K5: 41.4
A6: CJ Brown | B6: P1 | C6: 2015-06-24 | D6: 5.82 | E6: 25.05 | F6: 146.2 | G6: 12.08 | H6: 438 | I6: 8.69 | J6: NA | K6: 8.7
A7: CJ Brown | B7: P1 | C7: 2015-06-24 | D7: 9.11 | E7: 24.89 | F7: 121.5 | G7: 10.04 | H7: 441 | I7: 8.53 | J7: NA | K7: 7.7
A8: CJ Brown | B8: P1 | C8: 2015-06-24 | D8: 12.42 | E8: 24.82 | F8: 107.3 | G8: 8.93 | H8: 443 | I8: 8.38 | J8: NA | K8: 8.1
A9: CJ Brown | B9: P1 | C9: 2015-06-24 | D9: 15.68 | E9: 23.69 | F9: 50.6 | G9: 4.28 | H9: 451 | I9: 7.97 | J9: NA | K9: 6.7
A10: CJ Brown | B10: P1 | C10: 2015-06-24 | D10: 19.02 | E10: 23.19 | F10: 33.7 | G10: 2.88 | H10: 450 | I10: 7.79 | J10: NA | K10: 6.6
A11: CJ Brown | B11: P1 | C11: 2015-06-24 | D11: 22.2 | E11: 21.75 | F11: 7.6 | G11: 0.68 | H11: 430 | I11: 7.66 | J11: NA | K11: 7.4
A12: CJ Brown | B12: P1 | C12: 2015-06-24 | D12: 25.5 | E12: 20.04 | F12: 1.2 | G12: 0.11 | H12: 475 | I12: 7.63 | J12: NA | K12: 7.4
A13: CJ Brown | B13: P1 | C13: 2015-06-24 | D13: 28.74 | E13: 18.71 | F13: 1.1 | G13: 0.1 | H13: 500 | I13: 7.6 | J13: NA | K13: 4.3
... A31: Harsha | B31: EMB | C31: 2015-07-06 | D31: 21.25 | E31: 13.22 | F31: 18.5 | G31: 1.94 | H31: 266 | I31: 8.18 | J31: NA | K31: 12.5
A32: Harsha | B32: EOF | C32: 2015-07-06 | D32: 0.3 | E32: 25.47 | F32: NA | G32: NA | H32: NA | I32: NA | J32: NA | K32: NA
A33: Harsha | B33: EOF | C33: 2015-07-06 | D33: 3.28 | E33: 25.47 | F33: 207.4 | G33: 16.98 | H33: 232 | I33: 9.6 | J33: NA | K33: 17.3
A34: Harsha | B34: EOF | C34: 2015-07-06 | D34: 14.11 | E34: 23.72 | F34: 15.8 | G34: 1.34 | H34: 249 | I34: 7.78 | J34: NA | K34: 3.1
A35: Harsha | B35: EOF | C35: 2015-07-06 | D35: 24.93 | E35: 22.21 | F35: 1.7 | G35: 0.15 | H35: 249 | I35: 7.65 | J35: NA | K35: 5
A36: Harsha | B36: EOF | C36: 2015-07-06 | D36: 35.76 | E36: 20.68 | F36: 1.7 | G36: 0.16 | H36: 244 | I36: 7.67 | J36: NA | K36: 6.4
A37: Harsha | B37: EOF | C37: 2015-07-06 | D37: 46.59 | E37: 17.54 | F37: 1.6 | G37: 0.15 | H37: 235 | I37: 7.72 | J37: NA | K37: 13.1
A38: Harsha | B38: EOF | C38: 2015-07-06 | D38: 57.41 | E38: 14.53 | F38: 1.4 | G38: 0.14 | H38: 225 | I38: 7.75 | J38: NA | K38: 13.4
A39: Harsha | B39: EOF | C39: 2015-07-06 | D39: 68.24 | E39: 13.36 | F39: 1.8 | G39: 0.19 | H39: 234 | I39: 7.8 | J39: NA | K39: 11.6
A40: Harsha | B40: EOF | C40: 2015-07-06 | D40: 79 | E40: 12.54 | F40: 2.2 | G40: 0.23 | H40: 239 | I40: 7.86 | J40: NA | K40: 11.4
A41: Harsha | B41: EOF | C41: 2015-07-06 | D41: 89.9 | E41: 11.38 | F41: 3.7 | G41: 0.4 | H41: 239 | I41: 7.96 | J41: NA | K41: 13.9
A42: Harsha | B42: EOF | C42: 2015-07-06 | D42: 100.72 | E42: 10.12 | F42: 7.7 | G42: 0.87 | H42: 252 | I42: 8.05 | J42: NA | K42: 28.9
A43: CJ Brown | B43: P1 | C43: 2015-07-08 | D43: 0.118 | E43: 23.48 | F43: 91 | G43: 7.72 | H43: 441 | I43: 8.51 | J43: NA | K43: 2.9
A44: CJ Brown | B44: P1 | C44: 2015-07-08 | D44: 29.95 | E44: 20.35 | F44: 4.8 | G44: 0.42 | H44: 491 | I44: 7.73 | J44: NA | K44: 4.7
... A56: Harsha | B56: EUS | C56: 2015-07-15 | D56: 15.118 | E56: 22.73 | F56: 79.3 | G56: 6.83 | H56: 168 | I56: 7.97 | J56: NA | K56: 132.8
A57: Harsha | B57: EFL | C57: 2015-07-16 | D57: 0.1 | E57: 26.2 | F57: 208 | G57: 16.1 | H57: 260 | I57: 9.73 | J57: -991.3 | K57: 17.2
A58: Harsha | B58: EFL | C58: 2015-07-16 | D58: 50 | E58: 22.1 | F58: 5.8 | G58: 0.5 | H58: 235 | I58: 8.51 | J58: -964 | K58: 11.7
A59: Harsha | B59: EOF | C59: 2015-07-16 | D59: 0.1 | E59: 28.6 | F59: 252.9 | G59: 19.69 | H59: 236 | I59: 9.85 | J59: -1000 | K59: 23.6
A60: Harsha | B60: EOF | C60: 2015-07-16 | D60: =CONVERT(33,"m","ft") -> 108.26772 | E60: 12.81 | F60: 5 | G60: 0.53 | H60: 253 | I60: 7.88 | J60: -990.7 | K60: 21.1
A61: Harsha | B61: EUS2 | C61: 2015-07-16 | D61: 0.1 | E61: 25.37 | F61: 110.5 | G61: 9.03 | H61: 226 | I61: 8.83 | J61: NA | K61: 19.3
A62: Harsha | B62: EUS2 | C62: 2015-07-16 | D62: 13.3 | E62: 22.66 | F62: 71.2 | G62: 6.15 | H62: 165 | I62: 8.06 | J62: -970 | K62: 91.4
A63: Harsha | B63: ECP | C63: 2015-07-22 | D63: 1.03 | E63: 28.64 | F63: 175.5 | G63: 13.56 | H63: 210 | I63: 9.18 | J63: -997.8 | K63: 17.1
A64: Harsha | B64: ECP | C64: 2015-07-22 | D64: 37.158 | E64: 23.47 | F64: 40.6 | G64: 3.42 | H64: 160 | I64: 8.02 | J64: -970.7 | K64: 51.5
A65: Harsha | B65: EEB | C65: 2015-07-22 | D65: 1.087 | E65: 27.54 | F65: 177.5 | G65: 13.97 | H65: 209 | I65: 9.12 | J65: -987.5 | K65: 19.1
